# 异常处理

> 原文：<https://csharp.net-tutorials.com/advanced/exceptions/>

在每个程序中，有时都会出错。有了 C#，我们有幸拥有一个好的编译器，它将帮助我们避免一些最常见的错误。显然它不能看到可能发生的每一个错误，在这些情况下。NET framework 将抛出一个异常，告诉我们出现了错误。在前面关于数组的一章中，我描述了如果我们试图把太多的项目放入一个数组中，我们会得到一个异常。让我们举个例子:

```
using System;
using System.Collections;

namespace ConsoleApplication1
{
    class Program
    {
    static void Main(string[] args)
    {
        int[] numbers = new int[2];

        numbers[0] = 23;
        numbers[1] = 32;
        numbers[2] = 42;

        foreach(int i in numbers)
        Console.WriteLine(i);
        Console.ReadLine();
    }
    }
}
```

好的，试着运行这个例子，你就会明白我在说什么了。你看到我们做错了什么吗？我们已经定义了一个整数数组，可以容纳 2 个元素，但是我们试图在其中使用 3 个空格。显然，这会导致一个错误，如果您尝试运行这个示例，就会看到这个错误。当在 Visual Studio 内部运行时，ide 为我们提供了一些异常选项，但是如果您试图通过简单地双击 EXE 文件来执行程序，您将会得到一个令人讨厌的错误。如果您知道可能会发生错误，您应该处理它。这是使用异常的地方。下面是上面代码的一个略微修改的版本:

```
int[] numbers = new int[2];
try
{
    numbers[0] = 23;
    numbers[1] = 32;
    numbers[2] = 42;

    foreach(int i in numbers)
    Console.WriteLine(i);
}
catch
{
    Console.WriteLine("Something went wrong!");
}
Console.ReadLine();
```

让我向您介绍一下在错误处理方面您的新朋友:the try..接住滑轮。现在试着运行这个程序，看看不同之处——不是 Visual Studio/Windows 告诉我们发生了一个严重的问题，而是我们讲述自己的故事。但是如果我们能知道哪里出了问题，那不是很好吗？没问题:

```
catch(Exception ex)
{
    Console.WriteLine("An error occured: " + ex.Message);
}
```

<input type="hidden" name="IL_IN_ARTICLE">

如您所见，我们在 catch 语句中添加了一些内容。我们现在告诉我们想要捕获哪个异常，在这种情况下是所有异常的基础，即异常。通过这样做，我们获得了一些关于导致异常的问题的信息，并且通过输出消息属性，我们获得了一个可以理解的问题描述。

正如我所说的，**异常**是最常见的异常类型。异常处理的规则告诉我们，我们应该总是使用最不通用的异常类型，在这种情况下，我们实际上知道代码生成的异常的确切类型。怎么会？因为 Visual Studio 在我们没有处理的时候就告诉我们了。如果您有疑问，文档通常会描述一个方法可能抛出的异常。找出答案的另一种方法是使用异常类告诉我们——将输出行改为:

```
Console.WriteLine("An error occured: " + ex.GetType().ToString());
```

结果正如预期的那样，是 IndexOutOfRangeException。因此，我们应该处理这个异常，但是没有什么可以阻止我们处理多个异常。在某些情况下，根据抛出的异常，您可能希望做不同的事情。只需将我们的 catch 块更改为以下内容:

```
catch(IndexOutOfRangeException ex)
{
    Console.WriteLine("An index was out of range!");
}
catch(Exception ex)
{
    Console.WriteLine("Some sort of error occured: " + ex.Message);
}
```

如您所见，我们首先寻找 IndexOutOfRangeException。如果我们反过来做，带有异常类的 catch 块就会得到它，因为所有的异常都是从它派生的。所以换句话说，你应该首先使用最具体的异常。

关于异常，您应该知道的另一件事是 finally 块。finally 块可以添加到一组 catch 块中，也可以独占使用，这取决于您的需要。finally 块中的代码总是 run - exception 或 no exception。如果您需要关闭文件引用或处置不再需要的对象，这是一个好地方。因为我们的例子到目前为止非常简单，所以我们实际上不需要任何清理，因为垃圾收集器会处理这些。但是，由于可能会遇到需要 finally 块的情况，这里是我们示例的扩展版本:

```
int[] numbers = new int[2];
try
{
    numbers[0] = 23;
    numbers[1] = 32;
    numbers[2] = 42;

    foreach(int i in numbers)
    Console.WriteLine(i);
}
catch(IndexOutOfRangeException ex)
{
    Console.WriteLine("An index was out of range!");
}
catch(Exception ex)
{
    Console.WriteLine("Some sort of error occured: " + ex.Message);
}
finally
{
    Console.WriteLine("It's the end of our try block. Time to clean up!");
}
Console.ReadLine();
```

如果您运行代码，您将看到第一个异常块和 finally 块都被执行了。如果您删除将数字 42 添加到数组的那一行，您将看到只到达了 finally 块。

关于异常，您应该知道的另一个重要部分是它们如何影响异常发生的方法。并非所有未处理的异常对您的应用程序都是致命的，但是当它们不是致命的时，您不应该期望执行方法的剩余代码。另一方面，如果您确实处理了异常，那么只有 try 块之后的代码行将被执行。在我们的示例中，输出数组值的循环永远不会到达，因为一旦抛出异常，try 块将直接进入 catch/finally 块。然而，到达了最后一行，我们从控制台读取数据以防止应用程序立即退出。在构造 try 块时，您应该始终记住这一点。

* * *